<?xml version='1.0'?>

<robot name="visual" xmlns:xacro="http://www.ros.org/wiki/xacro">

  <material name="blue">
    <color rgba="0 0 0.8 1"/>
  </material>
  <material name="black">
    <color rgba="0 0 0 1"/>
  </material>
  <material name="white">
    <color rgba="1 1 1 1"/>
  </material>

  <link name="base_link">
    <visual>
      <geometry>
        <cylinder length="0" radius="0"/>
      </geometry>
      <origin rpy="0 0 0" xyz="0 0 0.1524"/>
      <material name="blue"/>
    </visual>
  </link>

  <link name="right_base_outside">
    <visual>
      <geometry>
        <box size="0.0254 0.4572 0.2"/>
      </geometry>
      <origin rpy="0 0 0" xyz="0 0 0"/>
      <material name="white"/>
    </visual>
  </link>

  <link name="right_base_inside">
    <visual>
      <geometry>
        <box size="0.0254 0.4572 0.2"/>
      </geometry>
      <origin rpy="0 0 0" xyz="0 0 0"/>
      <material name="white"/>
    </visual>
  </link>

  <link name="left_base_outside">
    <visual>
      <geometry>
        <box size="0.0254 0.4572 0.2"/>
      </geometry>
      <origin rpy="0 0 0" xyz="0 0 0"/>
      <material name="white"/>
    </visual>
  </link>

  <link name="left_base_inside">
    <visual>
      <geometry>
        <box size="0.0254 0.4572 0.2"/>
      </geometry>
      <origin rpy="0 0 0" xyz="0 0 0"/>
      <material name="white"/>
    </visual>
  </link>

  <link name="left_front_wheel">
    <visual>
      <geometry>
        <cylinder radius="0.1524" length="0.0254"/>
      </geometry>
      <origin rpy="1.57075 1.57075 0" xyz="0 0 0"/>
      <material name="black"/>
    </visual>
  </link>

  <link name="left_back_wheel">
    <visual>
      <geometry>
        <cylinder radius="0.1524" length="0.0254"/>
      </geometry>
      <origin rpy="1.57075 1.57075 0" xyz="0 0 0"/>
      <material name="black"/>
    </visual>
  </link>

  <link name="right_front_wheel">
    <visual>
      <geometry>
        <cylinder radius="0.1524" length="0.0254"/>
      </geometry>
      <origin rpy="1.57075 1.57075 0" xyz="0 0 0"/>
      <material name="black"/>
    </visual>
  </link>

  <link name="right_back_wheel">
    <visual>
      <geometry>
        <cylinder radius="0.1524" length="0.0254"/>
      </geometry>
      <axis rpy="1 0 0" xyz="0 0 0"/>
      <origin rpy="1.57075 1.57075 0" xyz="0 0 0"/>
      <material name="black"/>
    </visual>
  </link>

  <link name="camera_link">
    <visual>
      <geometry>
        <box size="0.0254 0.1524 0.1143"/>
      </geometry>
      <origin rpy="0 0 0" xyz="0 0 0.1143"/>
      <material name="blue"/>
    </visual>
  </link>


  <joint name="base_link_to_right_base_outside" type="fixed">
    <parent link="base_link"/>
    <child link="right_base_outside"/>
    <origin xyz="0.2286 0 0.1524"/>
  </joint>

  <joint name="base_link_to_right_base_inside" type="fixed">
    <parent link="base_link"/>
    <child link="right_base_inside"/>
    <origin xyz="0.1524 0 0.1524"/>
  </joint>

  <joint name="base_link_to_left_base_outside" type="fixed">
    <parent link="base_link"/>
    <child link="left_base_outside"/>
    <origin xyz="-0.2286 0 0.1524"/>
  </joint>

  <joint name="base_link_to_left_base_inside" type="fixed">
    <parent link="base_link"/>
    <child link="left_base_inside"/>
    <origin xyz="-0.1524 0 0.1524"/>
  </joint>

  <joint name="base_link_to_left_front_wheel" type="continuous">
    <parent link="base_link"/>
    <child link="left_front_wheel"/>
    <origin rpy="1.57075 1.57075 0" xyz="0.1905 0.2286 0.1524"/>
    <axis rpy="0 0 0" xyz="0 1 0"/>
  </joint>

  <joint name="base_link_to_left_back_wheel" type="continuous">
    <axis rpy="0 0 0" xyz="0 1 0"/>
    <parent link="base_link"/>
    <child link="left_back_wheel"/>
    <origin rpy="1.57075 1.57075 0" xyz="0.1905 -0.2286 0.1524"/>
  </joint>

  <joint name="base_link_to_right_front_wheel" type="continuous">
    <axis rpy="0 0 0" xyz="0 1 0"/>
    <parent link="base_link"/>
    <child link="right_front_wheel"/>
    <origin rpy="1.57075 1.57075 0" xyz="-0.1905 0.2286 0.1524"/>
  </joint>

  <joint name="base_link_to_right_back_wheel" type="continuous">
    <axis rpy="0 0 0" xyz="0 1 0"/>
    <parent link="base_link"/>
    <child link="right_back_wheel"/>
    <origin rpy="1.57075 1.57075 0" xyz="-0.1905 -0.2286 0.1524"/>
  </joint>

  <joint name="base_link_to_camera" type="fixed">
    <parent link="base_link"/>
    <child link="camera_link"/>
    <origin xyz="0 0 0.1143"/>
  </joint>

  <link name="laser">
		</link>

		<joint name="base_link_to_laser" type="fixed">
			<parent link="base_link"/>
			<child link="laser"/>
			<origin xyz="0.0 0.0 0.3" rpy="0.0 0.0 3.14192" />
			<axis xyz="0 0 0"/>
		</joint>

</robot>
